Workbook

Sheet Raw Data
A1: Order ID | B1: Order Date | C1: Customer ID | D1: Customer Name | E1: Region | F1: Customer Segment | G1: Product Category | H1: Product | I1: Quantity | J1: Unit Price (₹) | K1: Discount (%) | L1: Sales (₹) | M1: Profit (₹) | N1: Payment Method | O1: Salesperson
A2: ORD1001 | B2: 45778 | C2: C101 | D2: Arun Kumar | E2: North | F2: Consumer | G2: Electronics | H2: Wireless Mouse | I2: 3 | J2: 850 | K2: 5 | L2: 2422.5 | M2: 363.38 | N2: UPI | O2: Rahul
A3: ORD1002 | B3: 45839 | C3: C102 | D3: Priya Menon | E3: South | F3: Corporate | G3: Electronics | H3: Keyboard | I3: 5 | J3: 1200 | K3: 10 | L3: 5400 | M3: 810 | N3: Credit Card | O3: Nikhil
A4: ORD1003 | B4: 45931 | C4: C103 | D4: Rahul Das | E4: East | F4: Consumer | G4: Furniture | H4: Office Chair | I4: 2 | J4: 6500 | K4: 5 | L4: 12350 | M4: 1852.5 | N4: Debit Card | O4: Arun
A5: ORD1004 | B5: 45992 | C5: C104 | D5: Neha Singh | E5: West | F5: Small Business | G5: Clothing | H5: Formal Shirt | I5: 8 | J5: 1500 | K5: 10 | L5: 10800 | M5: 1620 | N5: UPI | O5: Meera
A6: ORD1005 | B6: 15/01/2025 | C6: C105 | D6: Mohammed Ali | E6: North | F6: Consumer | G6: Home & Kitchen | H6: Electric Kettle | I6: 4 | J6: 1800 | K6: 5 | L6: 6840 | M6: 1026 | N6: Cash | O6: Fasil
A7: ORD1006 | B7: 18/01/2025 | C7: C106 | D7: Anjali Nair | E7: South | F7: Corporate | G7: Sports | H7: Running Shoes | I7: 3 | J7: 3500 | K7: 10 | L7: 9450 | M7: 1417.5 | N7: UPI | O7: Rahul
A8: ORD1007 | B8: 20/01/2025 | C8: C107 | D8: Vivek Sharma | E8: East | F8: Consumer | G8: Electronics | H8: USB Cable | I8: 10 | J8: 450 | K8: 0 | L8: 4500 | M8: 675 | N8: Credit Card | O8: Nikhil
A9: ORD1008 | B9: 23/01/2025 | C9: C108 | D9: Fathima KT | E9: West | F9: Corporate | G9: Furniture | H9: Study Table | I9: 2 | J9: 5500 | K9: 5 | L9: 10450 | M9: 1567.5 | N9: Debit Card | O9: Arun
A10: ORD1009 | B10: 25/01/2025 | C10: C109 | D10: Rohit Das | E10: North | F10: Small Business | G10: Clothing | H10: Jeans | I10: 6 | J10: 2200 | K10: 10 | L10: 11880 | M10: 1782 | N10: UPI | O10: Meera
A11: ORD1010 | B11: 28/01/2025 | C11: C110 | D11: Shreya Rao | E11: South | F11: Consumer | G11: Home & Kitchen | H11: Mixer Grinder | I11: 2 | J11: 4200 | K11: 5 | L11: 7980 | M11: 1197 | N11: Cash | O11: Fasil
A12: ORD1011 | B12: 45690 | C12: C111 | D12: Akash Kumar | E12: East | F12: Corporate | G12: Electronics | H12: Power Bank | I12: 5 | J12: 1600 | K12: 5 | L12: 7600 | M12: 1140 | N12: UPI | O12: Rahul
A13: ORD1012 | B13: 45749 | C13: C112 | D13: Divya Menon | E13: West | F13: Consumer | G13: Furniture | H13: Bookshelf | I13: 3 | J13: 4800 | K13: 10 | L13: 12960 | M13: 1944 | N13: Credit Card | O13: Nikhil
A14: ORD1013 | B14: 45810 | C14: C113 | D14: Sanjay Nair | E14: North | F14: Corporate | G14: Sports | H14: Cricket Bat | I14: 2 | J14: 5000 | K14: 5 | L14: 9500 | M14: 1425 | N14: Debit Card | O14: Arun
A15: ORD1014 | B15: 45902 | C15: C114 | D15: Ayesha Ali | E15: South | F15: Consumer | G15: Clothing | H15: Casual T-Shirt | I15: 10 | J15: 800 | K15: 10 | L15: 7200 | M15: 1080 | N15: UPI | O15: Meera
A16: ORD1015 | B16: 45963 | C16: C115 | D16: Kiran Kumar | E16: East | F16: Small Business | G16: Home & Kitchen | H16: Air Fryer | I16: 3 | J16: 6000 | K16: 5 | L16: 17100 | M16: 2565 | N16: Cash | O16: Fasil
A17: ORD1016 | B17: 14/02/2025 | C17: C116 | D17: Meera Joseph | E17: West | F17: Corporate | G17: Electronics | H17: Headphones | I17: 4 | J17: 2500 | K17: 10 | L17: 9000 | M17: 1350 | N17: Credit Card | O17: Rahul
A18: ORD1017 | B18: 17/02/2025 | C18: C117 | D18: Nikhil Raj | E18: North | F18: Consumer | G18: Furniture | H18: Dining Chair | I18: 6 | J18: 2800 | K18: 5 | L18: 15960 | M18: 2394 | N18: UPI | O18: Nikhil
A19: ORD1018 | B19: 20/02/2025 | C19: C118 | D19: Faisal Khan | E19: South | F19: Small Business | G19: Clothing | H19: Jacket | I19: 4 | J19: 3200 | K19: 10 | L19: 11520 | M19: 1728 | N19: Debit Card | O19: Arun
A20: ORD1019 | B20: 23/02/2025 | C20: C119 | D20: Anu Thomas | E20: East | F20: Consumer | G20: Sports | H20: Football | I20: 5 | J20: 1800 | K20: 5 | L20: 8550 | M20: 1282.5 | N20: UPI | O20: Meera
A21: ORD1020 | B21: 26/02/2025 | C21: C120 | D21: Ramesh Babu | E21: West | F21: Corporate | G21: Home & Kitchen | H21: Microwave Oven | I21: 2 | J21: 8500 | K21: 10 | L21: 15300 | M21: 2295 | N21: Cash | O21: Fasil
A22: ORD1021 | B22: 45691 | C22: C121 | D22: Manoj Kumar | E22: North | F22: Consumer | G22: Electronics | H22: Smart Watch | I22: 3 | J22: 4500 | K22: 5 | L22: 12825 | M22: 1923.75 | N22: UPI | O22: Rahul
A23: ORD1022 | B23: 45780 | C23: C122 | D23: Sneha Nair | E23: South | F23: Corporate | G23: Furniture | H23: Office Desk | I23: 2 | J23: 9000 | K23: 10 | L23: 16200 | M23: 2430 | N23: Credit Card | O23: Nikhil
A24: ORD1023 | B24: 45872 | C24: C123 | D24: Adil Ahmed | E24: East | F24: Small Business | G24: Clothing | H24: Formal Pant | I24: 7 | J24: 1800 | K24: 5 | L24: 11970 | M24: 1795.5 | N24: Debit Card | O24: Arun
A25: ORD1024 | B25: 45964 | C25: C124 | D25: Lakshmi Menon | E25: West | F25: Consumer | G25: Home & Kitchen | H25: Toaster | I25: 5 | J25: 1400 | K25: 0 | L25: 7000 | M25: 1050 | N25: UPI | O25: Meera
A26: ORD1025 | B26: 14/03/2025 | C26: C125 | D26: Deepak Raj | E26: North | F26: Corporate | G26: Sports | H26: Badminton Racket | I26: 4 | J26: 2400 | K26: 10 | L26: 8640 | M26: 1296 | N26: Cash | O26: Fasil
A27: ORD1026 | B27: 17/03/2025 | C27: C126 | D27: Swathi Kumar | E27: South | F27: Consumer | G27: Electronics | H27: Bluetooth Speaker | I27: 3 | J27: 3000 | K27: 5 | L27: 8550 | M27: 1282.5 | N27: UPI | O27: Rahul
A28: ORD1027 | B28: 20/03/2025 | C28: C127 | D28: Salman Khan | E28: East | F28: Corporate | G28: Furniture | H28: Sofa | I28: 1 | J28: 22000 | K28: 10 | L28: 19800 | M28: 2970 | N28: Credit Card | O28: Nikhil
A29: ORD1028 | B29: 23/03/2025 | C29: C128 | D29: Reshma Nair | E29: West | F29: Small Business | G29: Clothing | H29: Saree | I29: 5 | J29: 3500 | K29: 5 | L29: 16625 | M29: 2493.75 | N29: Debit Card | O29: Arun
A30: ORD1029 | B30: 26/03/2025 | C30: C129 | D30: Ajay Kumar | E30: North | F30: Consumer | G30: Home & Kitchen | H30: Refrigerator | I30: 1 | J30: 32000 | K30: 10 | L30: 28800 | M30: 4320 | N30: UPI | O30: Meera
A31: ORD1030 | B31: 29/03/2025 | C31: C130 | D31: Pooja Das | E31: South | F31: Corporate | G31: Sports | H31: Sports Watch | I31: 2 | J31: 5500 | K31: 5 | L31: 10450 | M31: 1567.5 | N31: Cash | O31: Fasil
A32: ORD1031 | B32: 45720 | C32: C131 | D32: Varun Nair | E32: East | F32: Consumer | G32: Electronics | H32: Wireless Mouse | I32: 6 | J32: 850 | K32: 5 | L32: 4845 | M32: 726.75 | N32: UPI | O32: Rahul
A33: ORD1032 | B33: 45812 | C33: C132 | D33: Amal Joseph | E33: West | F33: Corporate | G33: Furniture | H33: Office Chair | I33: 4 | J33: 6500 | K33: 10 | L33: 23400 | M33: 3510 | N33: Credit Card | O33: Nikhil
A34: ORD1033 | B34: 45904 | C34: C133 | D34: Shahid Ali | E34: North | F34: Small Business | G34: Clothing | H34: Formal Shirt | I34: 10 | J34: 1500 | K34: 5 | L34: 14250 | M34: 2137.5 | N34: Debit Card | O34: Arun
A35: ORD1034 | B35: 45995 | C35: C134 | D35: Reshma Paul | E35: South | F35: Consumer | G35: Home & Kitchen | H35: Electric Kettle | I35: 5 | J35: 1800 | K35: 10 | L35: 8100 | M35: 1215 | N35: UPI | O35: Meera
A36: ORD1035 | B36: 15/04/2025 | C36: C135 | D36: Vishnu Das | E36: East | F36: Corporate | G36: Sports | H36: Running Shoes | I36: 4 | J36: 3500 | K36: 5 | L36: 13300 | M36: 1995 | N36: Cash | O36: Fasil
A37: ORD1036 | B37: 18/04/2025 | C37: C136 | D37: Neethu Nair | E37: West | F37: Consumer | G37: Electronics | H37: Keyboard | I37: 3 | J37: 1200 | K37: 0 | L37: 3600 | M37: 540 | N37: Credit Card | O37: Rahul
A38: ORD1037 | B38: 21/04/2025 | C38: C137 | D38: Asif Rahman | E38: North | F38: Corporate | G38: Furniture | H38: Study Table | I38: 3 | J38: 5500 | K38: 10 | L38: 14850 | M38: 2227.5 | N38: UPI | O38: Nikhil
A39: ORD1038 | B39: 24/04/2025 | C39: C138 | D39: Anjali Menon | E39: South | F39: Small Business | G39: Clothing | H39: Jeans | I39: 8 | J39: 2200 | K39: 5 | L39: 16720 | M39: 2508 | N39: Debit Card | O39: Arun
A40: ORD1039 | B40: 27/04/2025 | C40: C139 | D40: Suresh Kumar | E40: East | F40: Consumer | G40: Home & Kitchen | H40: Mixer Grinder | I40: 4 | J40: 4200 | K40: 10 | L40: 15120 | M40: 2268 | N40: UPI | O40: Meera
...

Sheet Cleaned Data
A1: Order ID | B1: Order Date | C1: Customer ID | D1: Customer Name | E1: Region | F1: Customer Segment | G1: Product Category | H1: Product | I1: Quantity | J1: Unit Price (₹) | K1: DISCOUNT(%) | L1: Sales (₹) | M1: Profit (₹) | N1: Payment Method | O1: Salesperson
A2: ORD1001 | B2: 45778 | C2: C101 | D2: Arun Kumar | E2: North | F2: Consumer | G2: Electronics | H2: Wireless Mouse | I2: 3 | J2: 850 | K2: 0.05 | L2: 2422.5 | M2: 363.38 | N2: UPI | O2: Rahul
A3: ORD1002 | B3: 45779 | C3: C102 | D3: Priya Menon | E3: South | F3: Corporate | G3: Electronics | H3: Keyboard | I3: 5 | J3: 1200 | K3: 0.1 | L3: 5400 | M3: 810 | N3: Credit Card | O3: Nikhil
A4: ORD1003 | B4: 45780 | C4: C103 | D4: Rahul Das | E4: East | F4: Consumer | G4: Furniture | H4: Office Chair | I4: 2 | J4: 6500 | K4: 0.05 | L4: 12350 | M4: 1852.5 | N4: Debit Card | O4: Arun
A5: ORD1004 | B5: 45781 | C5: C104 | D5: Neha Singh | E5: West | F5: Small Business | G5: Clothing | H5: Formal Shirt | I5: 8 | J5: 1500 | K5: 0.1 | L5: 10800 | M5: 1620 | N5: UPI | O5: Meera
A6: ORD1005 | B6: 45782 | C6: C105 | D6: Mohammed Ali | E6: North | F6: Consumer | G6: Home & Kitchen | H6: Electric Kettle | I6: 4 | J6: 1800 | K6: 0.05 | L6: 6840 | M6: 1026 | N6: Cash | O6: Fasil
A7: ORD1006 | B7: 45783 | C7: C106 | D7: Anjali Nair | E7: South | F7: Corporate | G7: Sports | H7: Running Shoes | I7: 3 | J7: 3500 | K7: 0.1 | L7: 9450 | M7: 1417.5 | N7: UPI | O7: Rahul
A8: ORD1007 | B8: 45784 | C8: C107 | D8: Vivek Sharma | E8: East | F8: Consumer | G8: Electronics | H8: USB Cable | I8: 10 | J8: 450 | K8: 0 | L8: 4500 | M8: 675 | N8: Credit Card | O8: Nikhil
A9: ORD1008 | B9: 45785 | C9: C108 | D9: Fathima KT | E9: West | F9: Corporate | G9: Furniture | H9: Study Table | I9: 2 | J9: 5500 | K9: 0.05 | L9: 10450 | M9: 1567.5 | N9: Debit Card | O9: Arun
A10: ORD1009 | B10: 45786 | C10: C109 | D10: Rohit Das | E10: North | F10: Small Business | G10: Clothing | H10: Jeans | I10: 6 | J10: 2200 | K10: 0.1 | L10: 11880 | M10: 1782 | N10: UPI | O10: Meera
A11: ORD1010 | B11: 45787 | C11: C110 | D11: Shreya Rao | E11: South | F11: Consumer | G11: Home & Kitchen | H11: Mixer Grinder | I11: 2 | J11: 4200 | K11: 0.05 | L11: 7980 | M11: 1197 | N11: Cash | O11: Fasil
A12: ORD1011 | B12: 45788 | C12: C111 | D12: Akash Kumar | E12: East | F12: Corporate | G12: Electronics | H12: Power Bank | I12: 5 | J12: 1600 | K12: 0.05 | L12: 7600 | M12: 1140 | N12: UPI | O12: Rahul
A13: ORD1012 | B13: 45789 | C13: C112 | D13: Divya Menon | E13: West | F13: Consumer | G13: Furniture | H13: Bookshelf | I13: 3 | J13: 4800 | K13: 0.1 | L13: 12960 | M13: 1944 | N13: Credit Card | O13: Nikhil
... A51: ORD1050 | B51: 45827 | C51: C150 | D51: Amrutha Menon | E51: South | F51: Corporate | G51: Sports | H51: Badminton Racket | I51: 5 | J51: 2400 | K51: 0.05 | L51: 11400 | M51: 1710 | N51: Cash | O51: Fasil

Sheet Retail Domain & KPIs
A1: KPI | B1: Value
A2: Total Sales (Revenue) | B2: =SUM('Cleaned Data'!L2:L51) -> 603942.5
A3: Total Profit | B3: =SUM('Cleaned Data'!M2:M51) -> 90591.38
A4: Profit Margin | B4: 0.066666663
A5: Average Order Value (AOV) | B5: =AVERAGE('Cleaned Data'!L2:L51) -> 12078.85
A6: Total Quantity Sold | B6: =SUM('Cleaned Data'!I2:I51) -> 230
A7: Highest Sales | B7: =MAX('Cleaned Data'!L2:L51) -> 28800
A8: Lowest Sales | B8: =MIN('Cleaned Data'!L2:L51) -> 2422.5

Sheet KPI Explanation
A1: KPI | B1: Imapct discount on profit
A2: what KPI MEAUSURE | B2: Measures how the discount given on products affects the profit earned from sales.
A3: Why businesses track this metric | B3: Helps businesses understand whether discounts increase sales while maintaining profit, and whether high discounts reduce profitability.

Sheet Basic Analysis
A1: Total Sales by Product Category | F1: Profit by Customer Segment
A3: Product Category | B3: Total Sales | F3: Customer Segment | G3: Total Profit
A4: Electronics | B4: =SUMIF('Cleaned Data'!G2:G51,"Electronics",'Cleaned Data'!L2:L51) -> 82777.5 | F4: Consumer | G4: =SUMIF('Cleaned Data'!F2:F51,"Consumer",'Cleaned Data'!M2:M51) -> 33988.13
A5: Furniture | B5: =SUMIF('Cleaned Data'!G2:G51,"Furniture",'Cleaned Data'!L2:L51) -> 154770 | F5: Corporate | G5: =SUMIF('Cleaned Data'!F2:F51,"Corporate",'Cleaned Data'!M2:M51) -> 35869.5
A6: Clothing | B6: =SUMIF('Cleaned Data'!G4:G53,"Electronics",'Cleaned Data'!L4:L53) -> 74955 | F6: Small Business | G6: =SUMIF('Cleaned Data'!F2:F51,"Small Business",'Cleaned Data'!M2:M51) -> 20733.75
A7: Home & Kitchen | B7: =SUMIF('Cleaned Data'!G4:G53,"Furniture",'Cleaned Data'!L4:L53) -> 154770
A8: Sports | B8: =SUMIF('Cleaned Data'!G6:G55,"Electronics",'Cleaned Data'!L6:L55) -> 74955
A11: Total Sales by Region | F11: Quantity Sold by Product Category
A13: Region | B13: Total Sales | F13: Product Category | G13: Quantity Sold
A14: North | B14: =SUMIF('Cleaned Data'!E2:E51,"North",'Cleaned Data'!L2:L51) -> 172417.5 | F14: Electronics | G14: =SUMIF('Cleaned Data'!G2:G51,"Electronics",'Cleaned Data'!I2:I51) -> 55
A15: South | B15: =SUMIF('Cleaned Data'!E3:E52,"South",'Cleaned Data'!L3:L52) -> 133485 | F15: Furniture | G15: =SUMIF('Cleaned Data'!G3:G52,"Furniture",'Cleaned Data'!I3:I52) -> 33
A16: East | B16: =SUMIF('Cleaned Data'!E4:E53,"East",'Cleaned Data'!L4:L53) -> 144415 | F16: Clothing | G16: =SUMIF('Cleaned Data'!G4:G53,"Clothing",'Cleaned Data'!I4:I53) -> 76
A17: West | B17: =SUMIF('Cleaned Data'!E5:E54,"West",'Cleaned Data'!L5:L54) -> 153625 | F17: Home & Kitchen | G17: =SUMIF('Cleaned Data'!G5:G54,"Home & Kitchen",'Cleaned Data'!I5:I54) -> 31
F18: Sports | G18: =SUMIF('Cleaned Data'!G6:G55,"Sports",'Cleaned Data'!I6:I55) -> 35
